<?xml version="1.0" encoding="utf-8" ?>
<!-- This URDF was automatically created by SolidWorks to URDF Exporter! Originally created by
Stephen Brawner (brawner@gmail.com) 
     Commit Version: 1.6.0-4-g7f85cfe  Build Version: 1.6.7995.38578
     For more information, please see http://wiki.ros.org/sw_urdf_exporter -->
<robot name="yj10">
    <link name="world" />
    <joint name="base_joint" type="fixed">
        <parent link="world" />
        <child link="base_link" />
        <origin xyz="0.0 0.0 0.5" rpy="0.0 0.0 0.0" />
    </joint>
    <link name="base_link">
        <inertial>
            <origin xyz="0.00013467 -0.04325 0.025845" rpy="0 0 0" />
            <mass value="1.7019" />
            <inertia ixx="0.0071647" ixy="1.7821E-05" ixz="8.0419E-06" iyy="0.0034039"
                iyz="-6.1005E-05" izz="0.0097375" />
        </inertial>
        <visual>
            <origin xyz="0 0 0" rpy="0 0 0" />
            <geometry>
                <mesh filename="package://yj10_description/meshes/base_link.STL" />
            </geometry>
            <material name="">
                <color rgba="1 1 1 1" />
            </material>
        </visual>
        <collision>
            <origin xyz="0 0 0" rpy="0 0 0" />
            <geometry>
                <mesh filename="package://yj10_description/meshes/base_link.STL" />
            </geometry>
        </collision>
    </link>
    <link name="link1">
        <inertial>
            <origin xyz="0.0017435 -1.6818E-05 0.061315" rpy="0 0 0" />
            <mass value="0.87269" />
            <inertia ixx="0.0018566" ixy="3.7517E-07" ixz="-0.00012802" iyy="0.0018955"
                iyz="1.235E-06" izz="0.0010518" />
        </inertial>
        <visual>
            <origin xyz="0 0 0" rpy="0 0 0" />
            <geometry>
                <mesh filename="package://yj10_description/meshes/link1.STL" />
            </geometry>
            <material name="">
                <color rgba="1 1 1 1" />
            </material>
        </visual>
        <collision>
            <origin xyz="0 0 0" rpy="0 0 0" />
            <geometry>
                <mesh filename="package://yj10_description/meshes/link1.STL" />
            </geometry>
        </collision>
    </link>
    <joint name="joint1" type="revolute">
        <origin xyz="0 0 0.056" rpy="0 0 0" />
        <parent link="base_link" />
        <child link="link1" />
        <axis xyz="0 0 -1" />
        <limit lower="-1.5708" upper="1.5708" effort="10000" velocity="0.57" />
    </joint>
    <link name="link2">
        <inertial>
            <origin xyz="0.046603 -0.00044956 0.27133" rpy="0 0 0" />
            <mass value="3.09" />
            <inertia ixx="0.036472" ixy="-1.0215E-06" ixz="-1.8792E-05" iyy="0.036366"
                iyz="1.8127E-07" izz="0.0025346" />
        </inertial>
        <visual>
            <origin xyz="0 0 0" rpy="0 0 0" />
            <geometry>
                <mesh filename="package://yj10_description/meshes/link2.STL" />
            </geometry>
            <material name="">
                <color rgba="1 1 1 1" />
            </material>
        </visual>
        <collision>
            <origin xyz="0 0 0" rpy="0 0 0" />
            <geometry>
                <mesh filename="package://yj10_description/meshes/link2.STL" />
            </geometry>
        </collision>
    </link>
    <joint name="joint2" type="revolute">
        <origin xyz="0.038998 -0.00037619 0.093" rpy="0 0 0" />
        <parent link="link1" />
        <child link="link2" />
        <axis xyz="-0.99995 0.009646 0" />
        <limit lower="-1.5708" upper="1.5708" effort="10000" velocity="0.57" />
    </joint>
    <link name="link3">
        <inertial>
            <origin xyz="-0.028145 0.32599 -6.7599E-09" rpy="0 0 0" />
            <mass value="1.8688" />
            <inertia ixx="0.027421" ixy="-0.00023639" ixz="-4.1986E-10" iyy="0.00089832"
                iyz="2.8529E-11" izz="0.027448" />
        </inertial>
        <visual>
            <origin xyz="0 0 0" rpy="0 0 0" />
            <geometry>
                <mesh filename="package://yj10_description/meshes/link3.STL" />
            </geometry>
            <material name="">
                <color rgba="1 1 1 1" />
            </material>
        </visual>
        <collision>
            <origin xyz="0 0 0" rpy="0 0 0" />
            <geometry>
                <mesh filename="package://yj10_description/meshes/link3.STL" />
            </geometry>
        </collision>
    </link>
    <joint name="joint3" type="revolute">
        <origin xyz="0.0049998 -4.823E-05 0.6" rpy="0 0 0" />
        <parent link="link2" />
        <child link="link3" />
        <axis xyz="0.99995 -0.009646 0" />
        <limit lower="-1.5708" upper="1.5708" effort="10000" velocity="0.57" />
    </joint>
    <link name="link4">
        <inertial>
            <origin xyz="0.042982 -0.024425 2.0748E-09" rpy="0 0 0" />
            <mass value="0.63938" />
            <inertia ixx="0.0010731" ixy="5.6489E-07" ixz="3.7312E-11" iyy="0.00054075"
                iyz="-6.3284E-12" izz="0.0013552" />
        </inertial>
        <visual>
            <origin xyz="0 0 0" rpy="0 0 0" />
            <geometry>
                <mesh filename="package://yj10_description/meshes/link4.STL" />
            </geometry>
            <material name="">
                <color rgba="1 1 1 1" />
            </material>
        </visual>
        <collision>
            <origin xyz="0 0 0" rpy="0 0 0" />
            <geometry>
                <mesh filename="package://yj10_description/meshes/link4.STL" />
            </geometry>
        </collision>
    </link>
    <joint name="joint4" type="revolute">
        <origin xyz="0.014287 0.59989 0" rpy="0 0 0" />
        <parent link="link3" />
        <child link="link4" />
        <axis xyz="-0.99995 0.009646 0" />
        <limit lower="-1.5708" upper="1.5708" effort="10000" velocity="0.57" />
    </joint>
    <link name="link5">
        <inertial>
            <origin xyz="0.0014574 0.058849 0.00040131" rpy="0 0 0" />
            <mass value="0.22539" />
            <inertia ixx="9.0373E-05" ixy="-8.613E-07" ixz="4.3725E-09" iyy="7.106E-05"
                iyz="4.5328E-07" izz="0.00014085" />
        </inertial>
        <visual>
            <origin xyz="0 0 0" rpy="0 0 0" />
            <geometry>
                <mesh filename="package://yj10_description/meshes/link5.STL" />
            </geometry>
            <material name="">
                <color rgba="1 1 1 1" />
            </material>
        </visual>
        <collision>
            <origin xyz="0 0 0" rpy="0 0 0" />
            <geometry>
                <mesh filename="package://yj10_description/meshes/link5.STL" />
            </geometry>
        </collision>
    </link>
    <joint name="joint5" type="revolute">
        <origin xyz="0.041038 0.055577 0" rpy="0 0 0" />
        <parent link="link4" />
        <child link="link5" />
        <axis xyz="-0.009646 -0.99995 0" />
        <limit lower="-1.5708" upper="1.5708" effort="10000" velocity="0.57" />
    </joint>

    <!-- For Gazebo -->

    <transmission name="trans_joint1">
        <type>transmission_interface/SimpleTransmission</type>
        <joint name="joint1">
            <hardwareInterface>hardware_interface/PositionJointInterface</hardwareInterface>
        </joint>
        <actuator name="joint1_motor">
            <hardwareInterface>hardware_interface/PositionJointInterface</hardwareInterface>
            <mechanicalReduction>1</mechanicalReduction>
        </actuator>
    </transmission>
    <transmission name="trans_joint2">
        <type>transmission_interface/SimpleTransmission</type>
        <joint name="joint2">
            <hardwareInterface>hardware_interface/PositionJointInterface</hardwareInterface>
        </joint>
        <actuator name="joint2_motor">
            <hardwareInterface>hardware_interface/PositionJointInterface</hardwareInterface>
            <mechanicalReduction>1</mechanicalReduction>
        </actuator>
    </transmission>
    <transmission name="trans_joint3">
        <type>transmission_interface/SimpleTransmission</type>
        <joint name="joint3">
            <hardwareInterface>hardware_interface/PositionJointInterface</hardwareInterface>
        </joint>
        <actuator name="joint3_motor">
            <hardwareInterface>hardware_interface/PositionJointInterface</hardwareInterface>
            <mechanicalReduction>1</mechanicalReduction>
        </actuator>
    </transmission>
    <transmission name="trans_joint4">
        <type>transmission_interface/SimpleTransmission</type>
        <joint name="joint4">
            <hardwareInterface>hardware_interface/PositionJointInterface</hardwareInterface>
        </joint>
        <actuator name="joint4_motor">
            <hardwareInterface>hardware_interface/PositionJointInterface</hardwareInterface>
            <mechanicalReduction>1</mechanicalReduction>
        </actuator>
    </transmission>
    <transmission name="trans_joint5">
        <type>transmission_interface/SimpleTransmission</type>
        <joint name="joint5">
            <hardwareInterface>hardware_interface/PositionJointInterface</hardwareInterface>
        </joint>
        <actuator name="joint5_motor">
            <hardwareInterface>hardware_interface/PositionJointInterface</hardwareInterface>
            <mechanicalReduction>1</mechanicalReduction>
        </actuator>
    </transmission>
    <gazebo>
        <plugin name="gazebo_ros_control" filename="libgazebo_ros_control.so">
            <robotNamespace>/</robotNamespace>
        </plugin>
    </gazebo>
</robot>
