<?xml version="1.0" encoding="utf-8"?>
<!-- This URDF was automatically created by SolidWorks to URDF Exporter! Originally created by
Stephen Brawner (brawner@gmail.com) 
     Commit Version: 1.6.0-4-g7f85cfe  Build Version: 1.6.7995.38578
     For more information, please see http://wiki.ros.org/sw_urdf_exporter -->
<robot name="yj10">
    <link name="world" />
    <joint name="base_joint" type="fixed">
        <parent link="world" />
        <child link="base_link" />
        <origin xyz="0.0 0.0 0.5" rpy="0.0 0.0 0.0" />
    </joint>
    <link name="base_link">
        <inertial>
            <origin xyz="0.000134667287995895 -0.0432500831535442 0.025845315360739" rpy="0 0 0" />
            <mass value="0.6" />
            <inertia ixx="1e-3" ixy="0.0" ixz="0.0" iyy="1e-3" iyz="0.0" izz="1e-3" />
        </inertial>
        <!-- <inertial>
            <origin xyz="0.000134667287995895 -0.0432500831535442 0.025845315360739" rpy="0 0 0" />
            <mass value="1.70194512971782" />
            <inertia ixx="0.00716472026950657" ixy="1.78214452851128E-05" ixz="8.04191431914254E-06"
                iyy="0.00340394281912895" iyz="-6.10052307905097E-05" izz="0.00973745717841389" />
        </inertial> -->
        <visual>
            <origin xyz="0 0 0" rpy="0 0 0" />
            <geometry>
                <mesh filename="package://yj10_description/meshes/base_link.STL" />
            </geometry>
            <material name="">
                <color rgba="1 1 1 1" />
            </material>
        </visual>
        <collision>
            <origin xyz="0 0 0" rpy="0 0 0" />
            <geometry>
                <mesh filename="package://yj10_description/meshes/base_link.STL" />
            </geometry>
        </collision>
    </link>
    <link name="link1">
        <inertial>
            <origin xyz="0.0017435 -6.9021E-17 0.061315" rpy="0 0 0" />
            <mass value="0.6" />
            <inertia ixx="1e-3" ixy="0.0" ixz="0.0" iyy="1e-3" iyz="0.0" izz="1e-3" />
        </inertial>
        <!-- <inertial>
            <origin xyz="0.0017435 -6.9021E-17 0.061315" rpy="0 0 0" />
            <mass value="0.87269" />
            <inertia ixx="0.0018566" ixy="-2.2587E-18" ixz="-0.00012803" iyy="0.0018955"
                iyz="-1.0839E-18" izz="0.0010518" />
        </inertial> -->
        <visual>
            <origin xyz="0 0 0" rpy="0 0 0" />
            <geometry>
                <mesh filename="package://yj10_description/meshes/link1.STL" />
            </geometry>
            <material name="">
                <color rgba="1 1 1 1" />
            </material>
        </visual>
        <collision>
            <origin xyz="0 0 0" rpy="0 0 0" />
            <geometry>
                <mesh filename="package://yj10_description/meshes/link1.STL" />
            </geometry>
        </collision>
    </link>
    <joint name="joint1" type="revolute">
        <origin xyz="0 0 0.056" rpy="0 0 0" />
        <parent link="base_link" />
        <child link="link1" />
        <axis xyz="0 0 -1" />
        <limit lower="-1.5708" upper="1.5708" effort="10000" velocity="0.57" />
    </joint>
    <link name="link2">
        <inertial>
            <origin xyz="0.046606 -1.5449E-17 0.27133" rpy="0 0 0" />
            <mass value="0.6" />
            <inertia ixx="1e-3" ixy="0.0" ixz="0.0" iyy="1e-3" iyz="0.0" izz="1e-3" />
        </inertial>
        <!-- <inertial>
            <origin xyz="0.046606 -1.5449E-17 0.27133" rpy="0 0 0" />
            <mass value="3.09" />
            <inertia ixx="0.036472" ixy="4.8405E-20" ixz="-1.8792E-05" iyy="0.036366"
                iyz="8.4789E-19" izz="0.0025346" />
        </inertial> -->
        <visual>
            <origin xyz="0 0 0" rpy="0 0 0" />
            <geometry>
                <mesh filename="package://yj10_description/meshes/link2.STL" />
            </geometry>
            <material name="">
                <color rgba="1 1 1 1" />
            </material>
        </visual>
        <collision>
            <origin xyz="0 0 0" rpy="0 0 0" />
            <geometry>
                <mesh filename="package://yj10_description/meshes/link2.STL" />
            </geometry>
        </collision>
    </link>
    <joint name="joint2" type="revolute">
        <origin xyz="0.039 0 0.093" rpy="0 0 0" />
        <parent link="link1" />
        <child link="link2" />
        <axis xyz="-1 0 0" />
        <limit lower="-1.5708" upper="1.5708" effort="10000" velocity="0.57" />
    </joint>
    <link name="link3">
        <inertial>
            <origin xyz="-0.031288 0.3257 -6.7668E-09" rpy="0 0 0" />
            <mass value="0.6" />
            <inertia ixx="1e-3" ixy="0.0" ixz="0.0" iyy="1e-3" iyz="0.0" izz="1e-3" />
        </inertial>
        <!-- <inertial>
            <origin xyz="-0.031288 0.3257 -6.7668E-09" rpy="0 0 0" />
            <mass value="1.8688" />
            <inertia ixx="0.027423" ixy="1.9482E-05" ixz="-4.2036E-10" iyy="0.00089622"
                iyz="2.4523E-11" izz="0.027448" />
        </inertial> -->
        <visual>
            <origin xyz="0 0 0" rpy="0 0 0" />
            <geometry>
                <mesh filename="package://yj10_description/meshes/link3.STL" />
            </geometry>
            <material name="">
                <color rgba="1 1 1 1" />
            </material>
        </visual>
        <collision>
            <origin xyz="0 0 0" rpy="0 0 0" />
            <geometry>
                <mesh filename="package://yj10_description/meshes/link3.STL" />
            </geometry>
        </collision>
    </link>
    <joint name="joint3" type="revolute">
        <origin xyz="0.005 0 0.6" rpy="0 0 0" />
        <parent link="link2" />
        <child link="link3" />
        <axis xyz="1 0 0" />
        <limit lower="-1.5708" upper="1.5708" effort="10000" velocity="0.57" />
    </joint>
    <link name="link4">
        <inertial>
            <origin xyz="0.043215 -0.024009 2.0697E-09" rpy="0 0 0" />
            <mass value="0.6" />
            <inertia ixx="1e-3" ixy="0.0" ixz="0.0" iyy="1e-3" iyz="0.0" izz="1e-3" />
        </inertial>
        <!-- <inertial>
            <origin xyz="0.043215 -0.024009 2.0697E-09" rpy="0 0 0" />
            <mass value="0.63938" />
            <inertia ixx="0.0010731" ixy="5.6999E-06" ixz="3.7743E-11" iyy="0.00054081"
                iyz="-6.1086E-12" izz="0.0013552" />
        </inertial> -->
        <visual>
            <origin xyz="0 0 0" rpy="0 0 0" />
            <geometry>
                <mesh filename="package://yj10_description/meshes/link4.STL" />
            </geometry>
            <material name="">
                <color rgba="1 1 1 1" />
            </material>
        </visual>
        <collision>
            <origin xyz="0 0 0" rpy="0 0 0" />
            <geometry>
                <mesh filename="package://yj10_description/meshes/link4.STL" />
            </geometry>
        </collision>
    </link>
    <joint name="joint4" type="revolute">
        <origin xyz="0.0085 0.6 0" rpy="0 0 0" />
        <parent link="link3" />
        <child link="link4" />
        <axis xyz="-1 0 0" />
        <limit lower="-1.5708" upper="1.5708" effort="10000" velocity="0.57" />
    </joint>
    <link name="link5">
        <inertial>
            <origin xyz="0.00088967 0.058861 0.00040131" rpy="0 0 0" />
            <mass value="0.6" />
            <inertia ixx="1e-3" ixy="0.0" ixz="0.0" iyy="1e-3" iyz="0.0" izz="1e-3" />
        </inertial>
        <!-- <inertial>
            <origin xyz="0.00088967 0.058861 0.00040131" rpy="0 0 0" />
            <mass value="0.22539" />
            <inertia ixx="9.0388E-05" ixy="-6.7485E-07" ixz="-8.312E-15" iyy="7.1045E-05"
                iyz="4.533E-07" izz="0.00014085" />
        </inertial> -->
        <visual>
            <origin xyz="0 0 0" rpy="0 0 0" />
            <geometry>
                <mesh filename="package://yj10_description/meshes/link5.STL" />
            </geometry>
            <material name="">
                <color rgba="1 1 1 1" />
            </material>
        </visual>
        <collision>
            <origin xyz="0 0 0" rpy="0 0 0" />
            <geometry>
                <mesh filename="package://yj10_description/meshes/link5.STL" />
            </geometry>
        </collision>
    </link>
    <joint name="joint5" type="revolute">
        <origin xyz="0.0405 0.05597 0" rpy="0 0 0" />
        <parent link="link4" />
        <child link="link5" />
        <axis xyz="0 -1 0" />
        <limit lower="-1.5708" upper="1.5708" effort="10000" velocity="0.57" />
    </joint>
    <link name="fake_link6">
        <inertial>
            <mass value="0.01" />
            <inertia ixx="1e-5" ixy="0.0" ixz="0.0" iyy="1e-5" iyz="0.0" izz="1e-5" />
        </inertial>
        <!-- <inertial>
            <mass value="0.22539" />
            <inertia ixx="9.0388E-05" ixy="0.0" ixz="0.0" iyy="7.1045E-05"
                iyz="0.0" izz="0.00014085" />
        </inertial> -->
        <visual>
            <origin xyz="0 0 0" rpy="0 0 0" />
            <geometry>
                <box size="0.01 0.01 0.01" />
            </geometry>
        </visual>
    </link>
    <joint name="joint6_fake" type="continuous">
        <parent link="link5" />
        <child link="fake_link6" />
        <axis xyz="0 0 1" />
        <origin xyz="0 0.145 0" rpy="0 0 0" />
    </joint>
    <!-- For Gazebo -->
    <transmission name="trans_joint1">
        <type>transmission_interface/SimpleTransmission</type>
        <joint name="joint1">
            <hardwareInterface>hardware_interface/PositionJointInterface</hardwareInterface>
            <!-- <hardwareInterface>hardware_interface/EffortJointInterface</hardwareInterface> -->
        </joint>
        <actuator name="joint1_motor">
            <mechanicalReduction>1</mechanicalReduction>
        </actuator>
    </transmission>
    <transmission name="trans_joint2">
        <type>transmission_interface/SimpleTransmission</type>
        <joint name="joint2">
            <hardwareInterface>hardware_interface/PositionJointInterface</hardwareInterface>
            <!-- <hardwareInterface>hardware_interface/EffortJointInterface</hardwareInterface> -->
        </joint>
        <actuator name="joint2_motor">
            <mechanicalReduction>1</mechanicalReduction>
        </actuator>
    </transmission>
    <transmission name="trans_joint3">
        <type>transmission_interface/SimpleTransmission</type>
        <joint name="joint3">
            <hardwareInterface>hardware_interface/PositionJointInterface</hardwareInterface>
            <!-- <hardwareInterface>hardware_interface/EffortJointInterface</hardwareInterface> -->
        </joint>
        <actuator name="joint3_motor">
            <mechanicalReduction>1</mechanicalReduction>
        </actuator>
    </transmission>
    <transmission name="trans_joint4">
        <type>transmission_interface/SimpleTransmission</type>
        <joint name="joint4">
            <hardwareInterface>hardware_interface/PositionJointInterface</hardwareInterface>
            <!-- <hardwareInterface>hardware_interface/EffortJointInterface</hardwareInterface> -->
        </joint>
        <actuator name="joint4_motor">
            <mechanicalReduction>1</mechanicalReduction>
        </actuator>
    </transmission>
    <transmission name="trans_joint5">
        <type>transmission_interface/SimpleTransmission</type>
        <joint name="joint5">
            <hardwareInterface>hardware_interface/PositionJointInterface</hardwareInterface>
            <!-- <hardwareInterface>hardware_interface/EffortJointInterface</hardwareInterface> -->
        </joint>
        <actuator name="joint5_motor">
            <mechanicalReduction>1</mechanicalReduction>
        </actuator>
    </transmission>
    <gazebo>
        <plugin name="gazebo_ros_control" filename="libgazebo_ros_control.so">
            <!-- <robotNamespace>/yj10</robotNamespace> -->
        </plugin>
    </gazebo>
    <transmission name="trans_joint6_fake">
        <type>transmission_interface/SimpleTransmission</type>
        <joint name="joint6_fake">
            <hardwareInterface>hardware_interface/PositionJointInterface</hardwareInterface>
            <!-- <hardwareInterface>hardware_interface/EffortJointInterface</hardwareInterface> -->
        </joint>
        <actuator name="joint6_fake_motor">
            <mechanicalReduction>1</mechanicalReduction>
        </actuator>
    </transmission>
</robot>